<?xml version="1.0" ?>
<!--
  Gazebo Ackermann steering plugin demo

  Try sending commands:

    gz topic -t "/model/vehicle_blue/cmd_vel" -m gz.msgs.Twist -p "linear: {x: 0.5}, angular: {z: 0.1}"

  Listen to odometry:

    gz topic -e -t /model/vehicle_blue/odometry

-->
<sdf version="1.6">
  <world name="ackermann_steering">

    <physics name="1ms" type="ignored">
      <max_step_size>0.001</max_step_size>
      <real_time_factor>1.0</real_time_factor>
    </physics>
    <plugin
      filename="gz-sim-physics-system"
      name="gz::sim::systems::Physics">
    </plugin>
    <plugin
      filename="gz-sim-user-commands-system"
      name="gz::sim::systems::UserCommands">
    </plugin>
    <plugin
      filename="gz-sim-scene-broadcaster-system"
      name="gz::sim::systems::SceneBroadcaster">
    </plugin>
    <!-- Enable the IMU sensor system -->
    <plugin filename="gz-sim-imu-system"
      name="gz::sim::systems::Imu">
    </plugin>

    <light type="directional" name="sun">
      <cast_shadows>true</cast_shadows>
      <pose>0 0 10 0 0 0</pose>
      <diffuse>1 1 1 1</diffuse>
      <specular>0.5 0.5 0.5 1</specular>
      <attenuation>
        <range>1000</range>
        <constant>0.9</constant>
        <linear>0.01</linear>
        <quadratic>0.001</quadratic>
      </attenuation>
      <direction>-0.5 0.1 -0.9</direction>
    </light>

    <model name="ground_plane">
      <static>true</static>
      <link name="link">
        <collision name="collision">
          <geometry>
            <plane>
              <normal>0 0 1</normal>
              <size>100 100</size>
            </plane>
          </geometry>
          <surface>
            <friction>
              <ode>
                <mu>50</mu>
              </ode>
              <bullet>
                <friction>1</friction>
                <rolling_friction>0.1</rolling_friction>
              </bullet>
            </friction>
          </surface>
        </collision>
        <visual name="visual">
          <geometry>
            <plane>
              <normal>0 0 1</normal>
              <size>100 100</size>
            </plane>
          </geometry>
          <material>
            <ambient>0.8 0.8 0.8 1</ambient>
            <diffuse>0.8 0.8 0.8 1</diffuse>
            <specular>0.8 0.8 0.8 1</specular>
          </material>
        </visual>
      </link>
    </model>

    <model name='vehicle_blue'>
      <pose degrees="true">0 2 0.325 0 0 90</pose>

      <link name='chassis'>
        <pose>-0.151427 -0 0.175 0 -0 0</pose>
        <inertial>
          <mass>1.14395</mass>
          <inertia>
            <ixx>0.126164</ixx>
            <ixy>0</ixy>
            <ixz>0</ixz>
            <iyy>0.416519</iyy>
            <iyz>0</iyz>
            <izz>0.481014</izz>
          </inertia>
        </inertial>
        <visual name='visual'>
          <geometry>
            <box>
              <size>2.01142 1 0.568726</size>
            </box>
          </geometry>
          <material>
            <ambient>0.5 0.5 1.0 1</ambient>
            <diffuse>0.5 0.5 1.0 1</diffuse>
            <specular>0.0 0.0 1.0 1</specular>
          </material>
        </visual>
        <collision name='collision'>
          <geometry>
            <box>
              <size>2.01142 1 0.568726</size>
            </box>
          </geometry>
        </collision>
        <!-- ArduPilot requires an IMU sensor oriented FRD in the body frame -->
        <sensor name="imu_sensor" type="imu">
          <pose degrees="true">0 0 0 180 0 0</pose>
          <always_on>1</always_on>
          <update_rate>1000</update_rate>
        </sensor>
      </link>

      <link name='front_left_wheel'>
        <pose>0.554283 0.625029 -0.025 -1.5707 0 0</pose>
        <inertial>
          <mass>2</mass>
          <inertia>
            <ixx>0.145833</ixx>
            <ixy>0</ixy>
            <ixz>0</ixz>
            <iyy>0.145833</iyy>
            <iyz>0</iyz>
            <izz>0.125</izz>
          </inertia>
        </inertial>
        <visual name='visual'>
          <geometry>
            <cylinder>
              <length>0.15</length>
              <radius>0.3</radius>
            </cylinder>
          </geometry>
          <material>
            <ambient>0.2 0.2 0.2 1</ambient>
            <diffuse>0.2 0.2 0.2 1</diffuse>
            <specular>0.2 0.2 0.2 1</specular>
          </material>
        </visual>
        <collision name='collision'>
          <geometry>
            <cylinder>
              <length>0.15</length>
              <radius>0.3</radius>
            </cylinder>
          </geometry>
          <surface>
            <friction>
              <ode>
                <mu>0.5</mu>
                <mu2>1.0</mu2>
                <fdir1>0 0 1</fdir1>
              </ode>
              <bullet>
                <friction>0.5</friction>
                <friction2>1</friction2>
                <rolling_friction>0.1</rolling_friction>
              </bullet>
            </friction>
          </surface>
        </collision>
      </link>

      <link name='rear_left_wheel'>
        <pose>-0.957138 0.625029 -0.025 -1.5707 0 0</pose>
        <inertial>
          <mass>2</mass>
          <inertia>
            <ixx>0.145833</ixx>
            <ixy>0</ixy>
            <ixz>0</ixz>
            <iyy>0.145833</iyy>
            <iyz>0</iyz>
            <izz>0.125</izz>
          </inertia>
        </inertial>
        <visual name='visual'>
          <geometry>
            <cylinder>
              <length>0.15</length>
              <radius>0.3</radius>
            </cylinder>
          </geometry>
          <material>
            <ambient>0.2 0.2 0.2 1</ambient>
            <diffuse>0.2 0.2 0.2 1</diffuse>
            <specular>0.2 0.2 0.2 1</specular>
          </material>
        </visual>
        <collision name='collision'>
          <geometry>
            <cylinder>
              <length>0.15</length>
              <radius>0.3</radius>
            </cylinder>
          </geometry>
          <surface>
            <friction>
              <ode>
                <mu>0.5</mu>
                <mu2>1.0</mu2>
                <fdir1>0 0 1</fdir1>
              </ode>
              <bullet>
                <friction>0.5</friction>
                <friction2>1</friction2>
                <rolling_friction>0.5</rolling_friction>
              </bullet>
            </friction>
          </surface>
        </collision>
      </link>

      <link name='front_right_wheel'>
        <pose>0.554282 -0.625029 -0.025 -1.5707 0 0</pose>
        <inertial>
          <mass>2</mass>
          <inertia>
            <ixx>0.145833</ixx>
            <ixy>0</ixy>
            <ixz>0</ixz>
            <iyy>0.145833</iyy>
            <iyz>0</iyz>
            <izz>0.125</izz>
          </inertia>
        </inertial>
        <visual name='visual'>
          <geometry>
            <cylinder>
              <length>0.15</length>
              <radius>0.3</radius>
            </cylinder>
          </geometry>
          <material>
            <ambient>0.2 0.2 0.2 1</ambient>
            <diffuse>0.2 0.2 0.2 1</diffuse>
            <specular>0.2 0.2 0.2 1</specular>
          </material>
        </visual>
        <collision name='collision'>
          <geometry>
            <cylinder>
              <length>0.15</length>
              <radius>0.3</radius>
            </cylinder>
          </geometry>
          <surface>
            <friction>
              <ode>
                <mu>0.5</mu>
                <mu2>1.0</mu2>
                <fdir1>0 0 1</fdir1>
              </ode>
              <bullet>
                <friction>0.5</friction>
                <friction2>1</friction2>
                <rolling_friction>0.1</rolling_friction>
              </bullet>
            </friction>
          </surface>
        </collision>
      </link>

      <link name='rear_right_wheel'>
        <pose>-0.957138 -0.625029 -0.025 -1.5707 0 0</pose>
        <inertial>
          <mass>2</mass>
          <inertia>
            <ixx>0.145833</ixx>
            <ixy>0</ixy>
            <ixz>0</ixz>
            <iyy>0.145833</iyy>
            <iyz>0</iyz>
            <izz>0.125</izz>
          </inertia>
        </inertial>
        <visual name='visual'>
          <geometry>
            <cylinder>
              <length>0.15</length>
              <radius>0.3</radius>
            </cylinder>
          </geometry>
          <material>
            <ambient>0.2 0.2 0.2 1</ambient>
            <diffuse>0.2 0.2 0.2 1</diffuse>
            <specular>0.2 0.2 0.2 1</specular>
          </material>
        </visual>
        <collision name='collision'>
          <geometry>
            <cylinder>
              <length>0.15</length>
              <radius>0.3</radius>
            </cylinder>
          </geometry>
          <surface>
            <friction>
              <ode>
                <mu>0.5</mu>
                <mu2>1.0</mu2>
                <fdir1>0 0 1</fdir1>
              </ode>
              <bullet>
                <friction>0.5</friction>
                <friction2>1</friction2>
                <rolling_friction>0.5</rolling_friction>
              </bullet>
            </friction>
          </surface>
        </collision>
      </link>

      <link name="front_left_wheel_steering_link">
        <pose>0.554283 0.5 0.02 0 0 0</pose>
        <inertial>
          <mass>0.5</mass>
          <inertia>
            <ixx>0.0153</ixx>
            <iyy>0.025</iyy>
            <izz>0.0153</izz>
          </inertia>
        </inertial>
        <visual name="steering_link_visual">
          <pose>0 0 0 0 0 0</pose>
          <geometry>
            <cylinder>
              <length>0.1</length>
              <radius>0.03</radius>
            </cylinder>
          </geometry>
          <material>
            <ambient>1 1 1</ambient>
            <diffuse>1 1 1</diffuse>
          </material>
        </visual>
      </link>

      <link name="front_right_wheel_steering_link">
        <pose>0.554283 -0.5 0.02 0 0 0</pose>
        <inertial>
          <mass>0.5</mass>
          <inertia>
            <ixx>0.0153</ixx>
            <iyy>0.025</iyy>
            <izz>0.0153</izz>
          </inertia>
        </inertial>
        <visual name="steering_link_visual">
          <pose>0 0 0 0 0 0</pose>
          <geometry>
            <cylinder>
              <length>0.1</length>
              <radius>0.03</radius>
            </cylinder>
          </geometry>
          <material>
            <ambient>1 1 1</ambient>
            <diffuse>1 1 1</diffuse>
          </material>
        </visual>
      </link>

      <joint name="front_left_wheel_steering_joint" type="revolute">
        <child>front_left_wheel_steering_link</child>
        <parent>chassis</parent>
        <axis>
          <xyz>0 0 1</xyz>
          <limit>
            <lower>-0.6</lower>
            <upper>+0.6</upper>
            <velocity>1.0</velocity>
            <effort>25</effort>
          </limit>
          <use_parent_model_frame>1</use_parent_model_frame>
        </axis>
      </joint>

      <joint name="front_right_wheel_steering_joint" type="revolute">
        <parent>chassis</parent>
        <child>front_right_wheel_steering_link</child>
        <axis>
          <xyz>0 0 1</xyz>
          <limit>
            <lower>-0.6</lower>
            <upper>+0.6</upper>
            <velocity>1.0</velocity>
            <effort>25</effort>
          </limit>
        </axis>
      </joint>

      <joint name='front_left_wheel_joint' type='revolute'>
        <parent>front_left_wheel_steering_link</parent>
        <child>front_left_wheel</child>
        <axis>
          <xyz>0 0 1</xyz>
          <limit>
            <lower>-1.79769e+308</lower>
            <upper>1.79769e+308</upper>
          </limit>
        </axis>
      </joint>

      <joint name='front_right_wheel_joint' type='revolute'>
        <parent>front_right_wheel_steering_link</parent>
        <child>front_right_wheel</child>
        <axis>
          <xyz>0 0 1</xyz>
          <limit>
            <lower>-1.79769e+308</lower>
            <upper>1.79769e+308</upper>
          </limit>
        </axis>
      </joint>

      <joint name='rear_left_wheel_joint' type='revolute'>
        <parent>chassis</parent>
        <child>rear_left_wheel</child>
        <axis>
          <xyz>0 0 1</xyz>
          <limit>
            <lower>-1.79769e+308</lower>
            <upper>1.79769e+308</upper>
          </limit>
        </axis>
      </joint>

      <joint name='rear_right_wheel_joint' type='revolute'>
        <parent>chassis</parent>
        <child>rear_right_wheel</child>
        <axis>
          <xyz>0 0 1</xyz>
          <limit>
            <lower>-1.79769e+308</lower>
            <upper>1.79769e+308</upper>
          </limit>
        </axis>
      </joint>

      <!--
        Modify the AckermannSteering plugin to be steering only as the ArduPilot
        plugin does not supply cmd_vel, but forwards steering and throttle
        commands separately.
      -->
      <plugin
        filename="gz-sim-ackermann-steering-system"
        name="gz::sim::systems::AckermannSteering">
        <steering_only>true</steering_only>
        <use_actuator_msg>false</use_actuator_msg>
        <left_joint>front_left_wheel_joint</left_joint>
        <left_joint>rear_left_wheel_joint</left_joint>
        <right_joint>front_right_wheel_joint</right_joint>
        <right_joint>rear_right_wheel_joint</right_joint>
        <left_steering_joint>front_left_wheel_steering_joint</left_steering_joint>
        <right_steering_joint>front_right_wheel_steering_joint</right_steering_joint>
        <kingpin_width>1.0</kingpin_width>
        <steering_limit>0.5</steering_limit>
        <wheel_base>1.0</wheel_base>
        <wheel_separation>1.25</wheel_separation>
        <wheel_radius>0.3</wheel_radius>
        <min_velocity>-1</min_velocity>
        <max_velocity>1</max_velocity>
        <min_acceleration>-3</min_acceleration>
        <max_acceleration>3</max_acceleration>
      </plugin>

      <!--
        Add a velocity controller for the left rear wheel.
      -->
      <plugin
        filename="gz-sim-joint-controller-system"
        name="gz::sim::systems::JointController">
        <joint_name>rear_left_wheel_joint</joint_name>
        <use_force_commands>true</use_force_commands>
        <use_actuator_msg>false</use_actuator_msg>
        <p_gain>0.1</p_gain>
        <i_gain>0.0</i_gain>
        <d_gain>0.0</d_gain>
      </plugin>

      <!--
        Add a velocity controller for the right rear wheel.
      -->
      <plugin
        filename="gz-sim-joint-controller-system"
        name="gz::sim::systems::JointController">
        <joint_name>rear_right_wheel_joint</joint_name>
        <use_force_commands>true</use_force_commands>
        <use_actuator_msg>false</use_actuator_msg>
        <p_gain>0.1</p_gain>
        <i_gain>0.0</i_gain>
        <d_gain>0.0</d_gain>
      </plugin>

      <!-- ArduPilot plugin

        Launch ArduPilot SITL with the command:
        
        sim_vehicle.py -D -v Rover -f rover -/-model JSON -/-enable-dds
        -/-console -/-map

        ('-/-' means a double hyphen in the terminal)

        The steering and throttle controllers need the PIDs increased from
        defaults for this frame. These values are a reasonable start.

        ATC_STR_RAT_P    2.500000 0.200000
        ATC_STR_RAT_D    0.010000 0.000000
        ATC_STR_RAT_FF   2.000000 0.750000
        ATC_SPEED_P      1.000000 0.100000
        ATC_SPEED_I      0.100000 0.200000
      -->
      <plugin name="ArduPilotPlugin"
        filename="ArduPilotPlugin">
        <fdm_addr>127.0.0.1</fdm_addr>
        <fdm_port_in>9002</fdm_port_in>
        <connectionTimeoutMaxCount>5</connectionTimeoutMaxCount>
        <lock_step>1</lock_step>
        <gazeboXYZToNED degrees="true">0 0 0 180 0 90</gazeboXYZToNED>
        <modelXYZToAirplaneXForwardZDown degrees="true">0 0 0 180 0 0</modelXYZToAirplaneXForwardZDown>
        <imuName>chassis::imu_sensor</imuName>

        <!-- steering -->
        <control channel="0">
          <jointName>front_left_wheel_steering_joint</jointName>
          <useForce>1</useForce>
          <multiplier>-1.571</multiplier>
          <offset>-0.5</offset>
          <servo_min>1000</servo_min>
          <servo_max>2000</servo_max>
          <type>COMMAND</type>
          <cmd_topic>/model/vehicle_blue/steer_angle</cmd_topic>
        </control>

        <!-- throttle -->
        <control channel="2">
          <jointName>rear_left_wheel_joint</jointName>
          <multiplier>100.0</multiplier>
          <offset>-0.5</offset>
          <servo_min>500</servo_min>
          <servo_max>2000</servo_max>
          <type>COMMAND</type>
          <cmd_topic>/model/vehicle_blue/joint/rear_left_wheel_joint/cmd_vel</cmd_topic>
        </control>
        <control channel="2">
          <jointName>rear_right_wheel_joint</jointName>
          <multiplier>100.0</multiplier>
          <offset>-0.5</offset>
          <servo_min>1000</servo_min>
          <servo_max>2000</servo_max>
          <type>COMMAND</type>
          <cmd_topic>/model/vehicle_blue/joint/rear_right_wheel_joint/cmd_vel</cmd_topic>
        </control>

      </plugin>

    </model>

  </world>
</sdf>
